Workbook

Sheet README
A1: Jyotish DE - Vedic Astrology App for the German Market
A2: Commercial build: free chart + free career fit feature + EUR 11 expert kundali evaluation
A4: Prepared for | B4: Siddharth Kala
A5: Date | B5: 1 August 2026
A6: Version | B6: v3 - supersedes the earlier paid-model and free-app plans
A7: Paid product | B7: Expert kundali evaluation - EUR 11.00 incl. 19% German VAT
A8: Free hook | B8: Career & Industry Fit: pick an industry, see strengths, growth areas and suggested roles
A9: Target market | B9: Germany (primary), Austria and Switzerland (secondary)
A10: Platform | B10: Flutter app (iOS + Android) + web consoles for astrologers and admin
A11: Payments | B11: Stripe web checkout - SEPA, Klarna, PayPal, cards, Apple/Google Pay (not store IAP)
A12: Engine | B12: Swiss Ephemeris FREE edition (AGPL-3.0), run CLIENT-SIDE only
A14: THE AGPL DECISION - READ THIS FIRST
A15: The problem | B15: The free Swiss Ephemeris is AGPL-3.0. Any code that calls it and serves users over a network must be published as open source. Running it on your backend would force you to open-source your entire commercial platform.
A16: The solution | B16: Run the ephemeris CLIENT-SIDE ONLY. In the mobile app via Dart FFI, in the astrologer console via WebAssembly. Publish one small package - bindings, WASM build, rule evaluator - as a public AGPL repo.
A17: What stays private | B17: Your backend, order and payment logic, astrologer console business logic, the industry-to-Jyotish mapping rules, all written content, and the astrologer marketplace.
A18: What becomes public | B18: Only the engine wrapper package. It contains no business logic and no competitive advantage.
A19: Cost saved | B19: CHF 750 (~EUR 800) one-off. Small - but the licence question had to be answered either way.
A20: Action required | B20: US-030 covers this. Have a software-licensing lawyer confirm the boundary before launch. This is the single most important technical decision in the plan.
A22: THE CAREER FEATURE (E16)
A23: What it is | B23: The user picks an industry. The app shows where they are naturally strong, where they will need more effort, and which roles within that industry suit them - all derived from classical Jyotish career indicators.
A24: How it works | B24: 10th house and its lord, D10 Dashamsha chart, Amatyakaraka, and the career grahas (Saturn, Mercury, Jupiter, Sun, Mars, Venus), weighted by dignity and cross-referenced with the current dasha.
A25: Why it matters | B25: It is the strongest free hook in the product. Career is the question people actually search for, and it feeds directly into the EUR 11 report.
A26: Deliberately NOT built | B26: The recruiter/employer version. An astrology tool used by an employer to assess a candidate is high-risk under the EU AI Act, engages GDPR Article 22 on automated decisions, and creates AGG discrimination exposure because birth date is an age proxy. US-102 contractually restricts the feature to personal use.
A28: HOW TO USE THIS WORKBOOK
A29: Tab | B29: What it contains
A30: Epics | B30: 16 epics with goal, business value, target release and owning role.
A31: User Stories | B31: 113 stories with acceptance criteria, MoSCoW priority, points, release and dependencies.
A32: Release Plan | B32: Sprint-by-sprint sequencing from kickoff to public launch.
A33: Tech Launch Checklist | B33: Everything that must exist technically before going live in Germany.
A34: Vendors & Costs | B34: Third-party services and indicative cost, plus unit economics at EUR 11.
A35: Team & Effort | B35: Roles required and the effort roll-up.
A36: Summary | B36: Live totals by epic, priority and release.
A38: CONVENTIONS
A39: Priority | B39: MoSCoW: Must / Should / Could
A40: Points | B40: Fibonacci. Assumed velocity on the Team & Effort tab - change the blue cell to re-plan.
A41: Release | B41: MVP = public launch | R1.1 = 4-8 weeks post-launch | R2 = quarter 2
A42: Yellow cells | B42: For you to fill in.
A44: ASSUMPTIONS
A45: 1 | B45: EUR 11 is inclusive of 19% German VAT, so net revenue is EUR 9.24 per order.
A46: 2 | B46: Astrologer fee assumed EUR 4.75; Stripe fee about EUR 0.42; infrastructure and PDF about EUR 0.15.
...

Sheet Epics
A1: Epic ID | B1: Epic Name | C1: Goal | D1: Business Value / Why | E1: Target Release | F1: Owning Role | G1: Stories | H1: Points | I1: Status
A2: E01 | B2: Foundation & Platform Setup | C2: Repo, CI/CD, EU environments, app shell and design system so feature work can ship daily. | D2: Enabler - nothing ships without it | E2: MVP | F2: Tech Lead | G2: =COUNTIF('User Stories'!$B$2:$B$200,$A2) | H2: =SUMIF('User Stories'!$B$2:$B$200,$A2,'User Stories'!$H$2:$H$200) | I2: To Do
A3: E02 | B3: Onboarding, Auth & Account | C3: Sign up, log in and manage profiles with minimal friction and GDPR-safe defaults. | D3: Activation funnel; every paid order needs an account | E3: MVP | F3: Mobile Lead | G3: =COUNTIF('User Stories'!$B$2:$B$200,$A3) | H3: =SUMIF('User Stories'!$B$2:$B$200,$A3,'User Stories'!$H$2:$H$200) | I3: To Do
A4: E03 | B4: Birth Data Capture & Time/Geo Resolution | C4: Collect date, exact time and birthplace; resolve to lat/long plus historical timezone offset. | D4: Wrong input = wrong chart = refunds. Highest-risk data path. | E4: MVP | F4: Backend Lead | G4: =COUNTIF('User Stories'!$B$2:$B$200,$A4) | H4: =SUMIF('User Stories'!$B$2:$B$200,$A4,'User Stories'!$H$2:$H$200) | I4: To Do
A5: E04 | B5: Vedic Calculation Engine (AGPL, client-side) | C5: Swiss Ephemeris free edition compiled into the app (FFI) and the web console (WASM), published as an open-source package. | D5: Core capability at zero licence cost, with the AGPL boundary drawn to protect proprietary code | E5: MVP | F5: Backend Lead | G5: =COUNTIF('User Stories'!$B$2:$B$200,$A5) | H5: =SUMIF('User Stories'!$B$2:$B$200,$A5,'User Stories'!$H$2:$H$200) | I5: To Do
A6: E05 | B6: Kundali Rendering & Free Insights | C6: North/South Indian and Western chart styles plus free auto-generated insight cards. | D6: Free value that drives install-to-paid conversion | E6: MVP | F6: Mobile Lead | G6: =COUNTIF('User Stories'!$B$2:$B$200,$A6) | H6: =SUMIF('User Stories'!$B$2:$B$200,$A6,'User Stories'!$H$2:$H$200) | I6: To Do
A7: E16 | B7: Career & Industry Fit (free feature) | C7: User picks an industry; the app shows where they are naturally strong, where they will need more effort, and which roles suit them. | D7: The strongest free hook in the product and the main funnel into the EUR 11 report | E7: MVP | F7: Product Owner | G7: =COUNTIF('User Stories'!$B$2:$B$200,$A7) | H7: =SUMIF('User Stories'!$B$2:$B$200,$A7,'User Stories'!$H$2:$H$200) | I7: To Do
A8: E06 | B8: Expert Kundali Evaluation - Customer Flow | C8: Order a EUR 11 expert evaluation, ask questions, track status, receive a PDF report. | D8: THE revenue product - EUR 11 per evaluation | E8: MVP | F8: Product Owner | G8: =COUNTIF('User Stories'!$B$2:$B$200,$A8) | H8: =SUMIF('User Stories'!$B$2:$B$200,$A8,'User Stories'!$H$2:$H$200) | I8: To Do
A9: E07 | B9: Astrologer Console (Expert Side) | C9: Vetted astrologers claim, analyse, write, QA and deliver evaluations to SLA. | D9: Supply side; without it the paid product cannot be fulfilled | E9: MVP | F9: Backend Lead | G9: =COUNTIF('User Stories'!$B$2:$B$200,$A9) | H9: =SUMIF('User Stories'!$B$2:$B$200,$A9,'User Stories'!$H$2:$H$200) | I9: To Do
A10: E08 | B10: Payments, Billing & German Tax | C10: Stripe payments with SEPA/Klarna/PayPal/cards, compliant invoices, VAT/OSS, refunds. | D10: Money in, legally | E10: MVP | F10: Backend Lead | G10: =COUNTIF('User Stories'!$B$2:$B$200,$A10) | H10: =SUMIF('User Stories'!$B$2:$B$200,$A10,'User Stories'!$H$2:$H$200) | I10: To Do
A11: E09 | B11: Localization & German Content | C11: Full de-DE and en-GB experience with culturally translated Vedic terminology. | D11: Germany is the target market - German is table stakes | E11: MVP | F11: Content Lead | G11: =COUNTIF('User Stories'!$B$2:$B$200,$A11) | H11: =SUMIF('User Stories'!$B$2:$B$200,$A11,'User Stories'!$H$2:$H$200) | I11: To Do
A12: E10 | B12: Notifications & Engagement | C12: Push, email and in-app messaging for order status, daily panchang and win-back. | D12: Retention and repeat purchase | E12: MVP | F12: Mobile Lead | G12: =COUNTIF('User Stories'!$B$2:$B$200,$A12) | H12: =SUMIF('User Stories'!$B$2:$B$200,$A12,'User Stories'!$H$2:$H$200) | I12: To Do
A13: E11 | B13: GDPR, Privacy & Legal Compliance | C13: Consent, DSR automation, EU residency, Impressum/AGB/Widerruf, age gating, disclaimers. | D13: Legal right to operate in Germany | E13: MVP | F13: Legal + Tech Lead | G13: =COUNTIF('User Stories'!$B$2:$B$200,$A13) | H13: =SUMIF('User Stories'!$B$2:$B$200,$A13,'User Stories'!$H$2:$H$200) | I13: To Do
... A17: E15 | B17: Post-MVP: Matchmaking, Horoscopes & Consultations | C17: Kundali Milan, daily horoscopes, live 1:1 consultations, subscriptions. | D17: Expands ARPU beyond one-off EUR 11 | E17: R2 | F17: Product Owner | G17: =COUNTIF('User Stories'!$B$2:$B$200,$A17) | H17: =SUMIF('User Stories'!$B$2:$B$200,$A17,'User Stories'!$H$2:$H$200) | I17: To Do
B18: TOTAL | G18: =SUM(G2:G17) | H18: =SUM(H2:H17)

Sheet User Stories
A1: Story ID | B1: Epic ID | C1: Epic Name | D1: Story Title | E1: User Story | F1: Acceptance Criteria | G1: Priority | H1: Points | I1: Release | J1: Component | K1: Depends On | L1: Status | M1: Sprint
A2: US-001 | B2: E01 | C2: Foundation & Platform Setup | D2: Monorepo & project scaffolding | E2: As a developer I want a monorepo with app, API and infra packages so that code, CI and shared types live in one place. | F2: 1) /app (Flutter), /api (proprietary services), /infra (IaC), /shared, and a SEPARATE public repo for the AGPL engine package. 2) Lint, format and pre-commit hooks enforced. 3) README with a local setup that works from a clean machine in under 30 minutes. | G2: Must | H2: 5 | I2: MVP | J2: DevOps | L2: Done
A3: US-002 | B3: E01 | C3: Foundation & Platform Setup | D3: CI/CD pipeline for app and API | E3: As a developer I want automated build, test and deploy pipelines so that every merge is releasable. | F3: 1) PR pipeline runs lint, tests and builds for iOS, Android and API. 2) Main merges auto-deploy to dev. 3) Tagged releases go to staging then prod with manual approval. 4) One-click rollback. | G3: Must | H3: 8 | I3: MVP | J3: DevOps | K3: US-001 | L3: To Do
A4: US-003 | B4: E01 | C4: Foundation & Platform Setup | D4: EU-region cloud environments (dev/staging/prod) | E4: As a tech lead I want three isolated EU-hosted environments so that we meet GDPR data-residency expectations. | F4: 1) All compute, DB, storage and backups in eu-central-1 (Frankfurt). 2) No production data in dev or staging. 3) Secrets in a managed store, never in the repo. 4) Defined in IaC and reproducible. DESCOPED (2026-08-01): single environment only for now (Hetzner, fsn1), pre-launch/pre-real-users — see infra/README.md. Full dev/staging/prod split must land before real users or payments go live. | G4: Must | H4: 8 | I4: MVP | J4: Infra | K4: US-001 | L4: In Progress
A5: US-004 | B5: E01 | C5: Foundation & Platform Setup | D5: Design system & component library | E5: As a designer I want a shared design system so that the UI is consistent and screens are built fast. | F5: 1) Tokens for colour, type, spacing, radii and elevation. 2) 20+ core components. 3) Light and dark themes. 4) Accessibility: 4.5:1 contrast minimum, 44pt tap targets. VERIFIED (2026-08-02): 28 components; contrast recomputed from the WCAG spec in test/design/contrast_test.dart (41 assertions, both themes); 44pt targets asserted per component incl. at 2x text scale. KNOWN DEBT: five German accessibility strings are hardcoded pending l10n (epic E09) — see the note in core/design/design_system.dart. | G5: Must | H5: 8 | I5: MVP | J5: Design | K5: US-001 | L5: Done
A6: US-005 | B6: E01 | C6: Foundation & Platform Setup | D6: App shell, navigation & offline state | E6: As a user I want fast navigation and graceful offline behaviour so that the app feels reliable. | F6: 1) Bottom tabs: Home, Kundali, Karriere, Auswertung, Profil. 2) Deep links resolve correctly. 3) Offline banner; cached chart viewable without network. 4) Cold start under 2.5s on mid-range Android. PARTIAL (2026-08-02). AC1 done: five tabs, state preserved per tab. AC2 done: routes tested and verified on device; a custom-scheme link was broken (host vs path) and is fixed. https App Links declared but cannot verify without the jyotish.de domain and a release signing key. AC3 HALF: offline banner works; "cached chart viewable without network" is not built — no chart exists to cache (needs E03 + the engine). AC4 NOT VERIFIED: release APK on an Android emulator cold-starts 2.19-2.47s, worst 2.63s under host load — at the 2.5s budget, not under it, and an emulator is not a mid-range device. Needs measuring on real hardware. | G6: Must | H6: 5 | I6: MVP | J6: Mobile | K6: US-004 | L6: In Progress
A7: US-006 | B7: E01 | C7: Foundation & Platform Setup | D7: Feature flags & remote config | E7: As a product owner I want feature flags so that we can dark-launch and kill-switch without a store release. | F7: 1) Flags evaluated per user and segment at runtime. 2) Kill switch on the paid evaluation flow. 3) All flag changes audited. PARTIAL (2026-08-02). AC1 engine done: segments (locale, platform, version range, user list, internal) and deterministic FNV-1a rollout bucketing, per flag so users are not in the same bucket for every rollout; 47 tests. CAVEAT: flagUserIdProvider is still a constant, so every device buckets identically — must be wired to real identity (E02) before any percentage rollout. AC2 done: paid_evaluation kill switch gates the Auswertung flow, cached so it survives restart and network loss; verified in widget tests. AC3 PARTIAL: FlagAuditService refuses any change without actor and reason, append-only, 12 tests — but storage is in-memory because the API has no database, and there is no admin UI or endpoint to change a flag. NO TRANSPORT: nothing serves the document and nothing fetches it, so flags are compiled-in defaults in practice until the API exists. | G7: Should | H7: 3 | I7: MVP | J7: Platform | K7: US-002 | L7: In Progress
A8: US-007 | B8: E01 | C8: Foundation & Platform Setup | D8: Centralised logging, metrics & alerting | E8: As an on-call engineer I want observability so that I detect incidents before users report them. | F8: 1) Structured logs with correlation IDs across app, API and workers. 2) Dashboards for latency, error rate and queue depth. 3) Alerts on p99 over 2s, 5xx over 1%, payment failures. 4) No PII or birth data in logs. PARTIAL (2026-08-02). AC4 DONE: allowlist-based redaction plus pattern scrubbing (email, IBAN, card, coordinates, birth dates, phone, token, IP) in both app and API, 48 tests including a full birth-data payload thrown at the logger. AC1 HALF: structured JSON loggers with correlation-ID propagation exist on both sides (AsyncLocalStorage in the API, Zone in the app), but there is no HTTP layer and no workers, so cross-service propagation is unexercised. AC2/AC3 DEFINED NOT DEPLOYED: alerts.yaml and dashboard.json encode the AC3 thresholds (p99 2s, 5xx 1%, payment failures) and CI fails if they are loosened, but there is no Grafana/Prometheus and the API emits no metrics, so every series referenced is absent and no alert can fire. A deadman rule (JyotishMetricsAbsent) is included precisely because silent non-firing is the failure mode here. | G8: Must | H8: 5 | I8: MVP | J8: Infra | K8: US-003 | L8: In Progress
A9: US-008 | B9: E01 | C9: Foundation & Platform Setup | D9: Crash reporting & performance monitoring | E9: As a mobile lead I want crash and ANR reporting so that stability regressions surface within hours. | F9: 1) Crash-free session rate tracked per release. 2) Symbolicated stack traces. 3) Alert below 99.0%. 4) Consent-gated in the EU. PARTIAL (2026-08-02). AC4 DONE: consent gate with per-category states, only "granted" permits transmission, pre-decision crashes buffered in memory and discarded on refusal, withdrawal takes effect immediately; reports redacted via US-007. Fixed a restore race that could re-grant consent a user had just refused. AC1 DONE locally: per-release session counters, unclean-exit detection verified on device — but nothing transmits the rate. AC2 PARTIAL: scripts/build_release.sh produces obfuscation symbols and refuses to return a build without them (verified, 3 ABIs), but there is no crash service to upload to, so nothing is actually symbolicated. AC3 DEFINED NOT DEPLOYED: JyotishCrashFreeRate alert with a 50-session guard, pinned by CI. BLOCKED ON: no crash reporting account (CrashTransport has only a recording implementation) and no CMP (US-095), so consent is never granted and nothing would send even if a transport existed. | G9: Must | H9: 3 | I9: MVP | J9: Mobile | K9: US-005 | L9: In Progress
A10: US-010 | B10: E02 | C10: Onboarding, Auth & Account | D10: First-run onboarding carousel | E10: As a new user I want a short intro so that I understand the value before signing up. | F10: 1) Maximum four screens, skippable. 2) German by default when the device locale is de. 3) Explains the free chart, the free career feature and the EUR 11 expert report. 4) Shown once, tracked as onboarding_completed. | G10: Should | H10: 3 | I10: MVP | J10: Mobile | K10: US-005 | L10: To Do
A11: US-011 | B11: E02 | C11: Onboarding, Auth & Account | D11: Email and password sign-up and login | E11: As a user I want to create an account so that my charts and orders are saved. | F11: 1) Email verification link. 2) Password minimum 10 characters with a breach-list check. 3) Rate limiting and lockout after 10 failed attempts. 4) Password reset token valid 30 minutes. | G11: Must | H11: 5 | I11: MVP | J11: Backend | K11: US-003 | L11: To Do
A12: US-012 | B12: E02 | C12: Onboarding, Auth & Account | D12: Sign in with Apple and Google | E12: As a user I want one-tap login so that I can start without typing a password. | F12: 1) Sign in with Apple mandatory on iOS if any social login is offered. 2) Google Sign-In on Android. 3) Account linking on matching email. 4) Apple private-relay addresses handled. | G12: Must | H12: 5 | I12: MVP | J12: Mobile | K12: US-011 | L12: To Do
A13: US-013 | B13: E02 | C13: Onboarding, Auth & Account | D13: Guest mode with later account claim | E13: As a curious visitor I want a chart without signing up so that I can evaluate the app first. | F13: 1) Full free chart and career page available as a guest. 2) Stored locally with an anonymous ID. 3) Guest data migrates on sign-up. 4) Checkout requires a real account. | G13: Should | H13: 5 | I13: MVP | J13: Mobile | K13: US-011 | L13: To Do
A14: US-014 | B14: E02 | C14: Onboarding, Auth & Account | D14: Profile management & multiple people | E14: As a user I want charts for family and friends so that I can order evaluations for them too. | F14: 1) Up to 10 saved profiles. 2) Name, birth data, relationship, optional photo. 3) Edit and delete with confirmation. 4) Editing birth data recalculates and warns if a paid report exists. | G14: Must | H14: 5 | I14: MVP | J14: Mobile | K14: US-030 | L14: To Do
... A114: US-128 | B114: E15 | C114: Post-MVP: Matchmaking, Horoscopes & Consultations | D114: Subscription tier | E114: As a frequent user I want a monthly plan so that I get ongoing value at a better price. | F114: 1) Monthly transit report, unlimited insights, discounted evaluations. 2) Store IAP required by Apple for subscriptions. 3) German auto-renewal disclosure rules met. 4) Churn dashboard. | G114: Could | H114: 21 | I114: R2 | J114: Payments | K114: US-079 | L114: To Do

Sheet Release Plan
A1: Phase | B1: Sprint | C1: Weeks | D1: Focus | E1: Key Epics | F1: Exit Criteria
A2: Discovery | B2: S0 | C2: Wk 1-2 | D2: AGPL boundary decision + licensing legal review, entity setup, astrologer sourcing, design system | E2: E01, E04, E11 | F2: Written AGPL decision record signed off by a lawyer; 5 astrologer candidates in pipeline
A3: Build | B3: S1 | C3: Wk 3-4 | D3: Repo split (public engine / private platform), CI/CD, EU infra, app shell, auth | E3: E01, E02 | F3: Signed build on TestFlight; a user can register
A4: Build | B4: S2 | C4: Wk 5-6 | D4: Swiss Ephemeris via FFI + WASM, published engine package | E4: E04 | F4: Identical chart output from the FFI and WASM builds on shared test vectors
A5: Build | B5: S3 | C5: Wk 7-8 | D5: Birth data capture, geocoding, historical timezone resolution | E5: E03 | F5: Correct UTC offset for 50 test births incl. German DST history
A6: Build | B6: S4 | C6: Wk 9-10 | D6: D1, D9, D10, dashas, yogas, chart snapshot upload | E6: E04 | F6: Engine matches astro.com on the golden-master suite
A7: Build | B7: S5 | C7: Wk 11-12 | D7: Chart rendering, free insight cards, glossary | E7: E05, E09 | F7: A user can generate and read their own chart end to end
A8: Build | B8: S6 | C8: Wk 13-14 | D8: CAREER FEATURE: significators, industry mapping, strengths, growth areas, roles | E8: E16 | F8: A user picks an industry and gets a coherent, astrologer-approved analysis
A9: Build | B9: S7 | C9: Wk 15-16 | D9: Stripe checkout, invoicing, VAT, webhook fulfilment | E9: E08 | F9: A EUR 11 test payment creates an order and issues a valid invoice
A10: Build | B10: S8 | C10: Wk 17-18 | D10: Astrologer console: queue, workbench (WASM), authoring | E10: E07 | F10: An astrologer can claim an order and write a report
A11: Build | B11: S9 | C11: Wk 19-20 | D11: Report PDF generation, delivery, status tracking, notifications | E11: E06, E10 | F11: Full happy path: pay, assign, write, deliver, read
A12: Build | B12: S10 | C12: Wk 21-22 | D12: Admin console, SLA escalation, refunds, support tooling | E12: E12 | F12: Support can resolve a refund and reassign an order unaided
... A18: Post-launch | B18: R2 | C18: Q2 | D18: Kundali Milan, horoscopes, live consultations, subscription | E18: E15 | F18: Second revenue line contributing over 20% of revenue

Sheet Tech Launch Checklist
A1: # | B1: Category | C1: Requirement | D1: Why it is required | E1: Blocking? | F1: Owner | G1: Status
A2: 1 | B2: Licensing | C2: Written AGPL boundary decision record | D2: Defines exactly where AGPL code runs (client only) and what must be published. Get this wrong and your whole backend becomes open source. | E2: Yes | F2: Tech Lead | G2: To Do
A3: 2 | B3: Licensing | C3: Public AGPL-3.0 repo containing the engine package (FFI bindings, WASM build, rule evaluator) | D3: This is what satisfies the AGPL obligation and lets you use the free ephemeris. | E3: Yes | F3: Tech Lead | G3: To Do
A4: 3 | B4: Licensing | C4: Software-licensing lawyer review of the client-side boundary | D4: The one legal opinion worth paying for here. AGPL section 13 network clause is the risk. | E4: Yes | F4: Legal | G4: To Do
A5: 4 | B5: Licensing | C5: Verified: the proprietary backend never links, bundles or calls Swiss Ephemeris | D5: If it does, the backend is a derivative work and must be published. | E5: Yes | F5: Tech Lead | G5: To Do
A6: 5 | B6: Licensing | C6: AGPL and GeoNames notices visible in-app under About, with repo link | D6: Both licences require attribution. | E6: Yes | F6: Mobile | G6: To Do
A7: 6 | B7: Legal entity | C7: German or EU legal entity (UG/GmbH) with USt-IdNr. | D7: Required to open Stripe, issue VAT invoices and publish a valid Impressum. | E7: Yes | F7: Founder | G7: To Do
A8: 7 | B8: Legal entity | C8: SEPA-capable business bank account | D8: Stripe payout destination. | E8: Yes | F8: Founder | G8: To Do
A9: 8 | B9: Legal | C9: Impressum, AGB, Datenschutzerklaerung, Widerrufsbelehrung in German | D9: DDG and BGB requirements. Missing or wrong Widerruf extends the cancellation window to 12 months + 14 days. | E9: Yes | F9: Legal | G9: To Do
A10: 9 | B10: Legal | C10: Explicit consent to start work before the 14-day withdrawal period ends | D10: Lets you begin the evaluation immediately without refund exposure. | E10: Yes | F10: Legal | G10: To Do
A11: 10 | B11: Legal | C11: Freelancer contracts plus AVV with every astrologer | D11: Astrologers process personal data; GDPR Article 28 requires a written agreement. | E11: Yes | F11: Legal | G11: To Do
A12: 11 | B12: Legal | C12: CAREER FEATURE: terms of service restricting it to personal use only | D12: Keeps you out of EU AI Act high-risk employment scope, GDPR Article 22 and AGG exposure. No B2B API, no bulk analysis, no candidate comparison. | E12: Yes | F12: Legal | G12: To Do
A13: 12 | B13: Legal | C13: Career content reviewed for non-deterministic, non-fatalistic language | D13: Consumer protection and basic responsibility. No claims about earnings or hiring outcomes. | E13: Yes | F13: Content | G13: To Do
... A50: 49 | B50: Growth | C50: Feature flags with a kill switch on the paid flow | D50: Lets you stop taking money instantly if fulfilment breaks. | E50: Yes | F50: Tech Lead | G50: To Do

Sheet Vendors & Costs
A1: Category | B1: Vendor / Item | C1: Purpose | D1: Pricing basis | E1: One-off (EUR) | F1: Monthly (EUR) | G1: Notes
A2: Engine | B2: Swiss Ephemeris (free AGPL edition) | C2: Astronomical calculations | D2: Free | E2: 0 | F2: 0 | G2: EUR 0. Trade-off: the engine package repo must be public. Professional licence would have been CHF 750.
A3: Geo | B3: Geocoding / GeoNames dataset | C3: Birthplace to lat/long | D3: Free or per 1k requests | E3: 0 | F3: 60 | G3: Bundle GeoNames offline where possible to cut this to zero.
A4: Cloud | B4: AWS/GCP eu-central-1 | C4: API, DB, storage, queue, PDF workers | D4: Usage | E4: 0 | F4: 480 | G4: Lower than the original plan because chart computation moved to the client.
A5: Payments | B5: Stripe | C5: Checkout, invoicing, payouts | D5: ~1.5% + EUR 0.25 EU cards | E5: 0 | F5: 0 | G5: About EUR 0.42 per EUR 11 order. Klarna and PayPal cost more.
A6: Payments | B6: Stripe Tax or equivalent | C6: VAT determination and OSS reporting | D6: 0.4-0.5% of transactions | E6: 0 | F6: 60 | G6: Alternative: manual OSS filing via a Steuerberater.
A7: Email | B7: Postmark / SendGrid | C7: Transactional email | D7: Per 10k emails | E7: 0 | F7: 40
A8: Push | B8: Firebase Cloud Messaging | C8: Push notifications | D8: Free tier | E8: 0 | F8: 0 | G8: Check EU data-transfer terms.
A9: Analytics | B9: PostHog EU / Amplitude | C9: Product analytics | D9: Per monthly tracked user | E9: 0 | F9: 150 | G9: Choose an EU-hosted plan.
A10: Consent | B10: Usercentrics / Cookiebot | C10: GDPR consent management | D10: Per app | E10: 0 | F10: 50 | G10: A German vendor is easier to defend to a DPA.
A11: Monitoring | B11: Sentry + Grafana Cloud | C11: Crashes, logs, metrics, alerts | D11: Per event/seat | E11: 0 | F11: 120 | G11: Scrub PII before ingestion.
A12: AI | B12: EU-hosted LLM endpoint | C12: Astrologer drafting assistant | D12: Per token | E12: 0 | F12: 200 | G12: Must be DPA-covered; the astrologer always approves output.
A13: Support | B13: Zendesk / Freshdesk | C13: Ticketing with German macros | D13: Per agent | E13: 0 | F13: 90 | G13: Two agents assumed.
A14: Stores | B14: Apple Developer Program | C14: iOS distribution | D14: Annual | E14: 0 | F14: 8 | G14: EUR 99/year.
A15: Stores | B15: Google Play Console | C15: Android distribution | D15: One-off | E15: 25 | F15: 0 | G15: USD 25 one-off.
A16: Legal | B16: German lawyer - AGB, Datenschutz, Widerruf, DPIA | C16: Compliance documents | D16: Project fee | E16: 4500 | F16: 0 | G16: Range EUR 3,000-6,000. Non-negotiable.
A17: Legal | B17: Software-licensing lawyer - AGPL boundary opinion | C17: Confirms the client-side boundary protects your backend | D17: Project fee | E17: 1500 | F17: 0 | G17: NEW and important. Cheaper than open-sourcing your platform by accident.
A18: Legal | B18: Employment lawyer - career feature terms review | C18: Confirms the personal-use restriction keeps you out of AI Act scope | D18: Project fee | E18: 800 | F18: 0 | G18: NEW. One-off review of the ToS wording.
A19: Legal | B19: External DPO if required | C19: GDPR oversight | D19: Retainer | E19: 0 | F19: 250 | G19: Take advice on whether you need one.
... A22: Content | B22: Bilingual astrologer content review | C22: Terminology, style guide, career rule sign-off | D22: Project fee | E22: 3500 | F22: 0 | G22: Increased from the original plan - the career rule set needs expert sign-off.
A23: Content | B23: Translation management (Lokalise/Crowdin) | C23: de-DE and en-GB strings | D23: Per seat | E23: 0 | F23: 60
B24: TOTAL | E24: =SUM(E2:E23) | F24: =SUM(F2:F23)
B26: Year-1 run cost (12 months) | F26: =F24*12
B27: Year-1 total incl. one-offs | F27: =F24*12+E24
B30: UNIT ECONOMICS PER EVALUATION
B31: Gross price charged (incl. 19% VAT) | C31: 11 | D31: Your stated price
B32: VAT rate | C32: 0.19 | D32: German standard rate
B33: Net revenue | C33: =C31/(1+C32) | D33: Calculated: gross divided by 1.19
B34: VAT payable to Finanzamt | C34: =C31-C33 | D34: Calculated: gross minus net
B35: Astrologer fee | C35: 4.75 | D35: Assumption - negotiate with astrologers
B36: Payment processing | C36: 0.42 | D36: Stripe EU card blend
B37: Infrastructure, PDF and email | C37: 0.15 | D37: Assumption
B38: Contribution margin per order | C38: =C33-C35-C36-C37
B39: Contribution margin % | C39: =IF(C33=0,0,C38/C33)
B41: Orders/month to cover monthly run cost | C41: =IF(C38<=0,0,ROUNDUP(F24/C38,0)) | D41: Operating cost only; excludes salaries and one-offs.

Sheet Team & Effort
A1: Role | B1: FTE for MVP | C1: Responsibility | D1: Outsourceable? | E1: Indicative cost (EUR/month)
A2: Product Owner / Founder | B2: 1 | C2: Scope, pricing, astrologer relationships, launch decisions | D2: No | E2: 0
A3: Tech Lead / Architect | B3: 1 | C3: Architecture, AGPL boundary, engine package, security | D3: No | E3: 9000
A4: Flutter Developer | B4: 2 | C4: iOS + Android app, FFI integration, chart rendering, career UI | D4: Yes | E4: 14000
A5: Backend Developer | B5: 1.5 | C5: APIs, payments, orders, PDF pipeline, admin, WASM console | D5: Yes | E5: 11000
A6: DevOps / SRE | B6: 0.5 | C6: IaC, CI/CD, observability, on-call | D6: Yes | E6: 4500
A7: UI/UX Designer | B7: 1 | C7: Design system, chart UX, career feature UX | D7: Yes | E7: 6000
A8: QA Engineer | B8: 1 | C8: Test automation, accuracy suite, device testing | D8: Yes | E8: 5500
A9: Vedic Astrology Consultant | B9: 0.5 | C9: Rule validation, industry mapping sign-off, astrologer vetting | D9: Yes | E9: 3000
A10: German Content Editor | B10: 0.5 | C10: Translation quality, terminology, career tone review | D10: Yes | E10: 2500
A11: Astrologers (fulfilment) | B11: 0 | C11: Write evaluations - paid per report, not salaried | D11: Yes | E11: 0
A12: Customer Support (German) | B12: 1 | C12: Tickets, refunds, SLA communication | D12: Yes | E12: 3500
A13: TOTAL | B13: =SUM(B2:B12) | E13: =SUM(E2:E12)
A15: Total story points (all releases) | B15: =SUM('User Stories'!H2:H200)
A16: MVP story points | B16: =SUMIF('User Stories'!I2:I200,"MVP",'User Stories'!H2:H200)
A17: Assumed velocity (points / 2-week sprint) | B17: 60
A18: Estimated MVP sprints | B18: =ROUNDUP(B16/B17,0)
A19: Estimated MVP calendar weeks (incl. 2-week discovery) | B19: =B18*2+2

Sheet Summary
A1: POINTS BY RELEASE
A2: Release | B2: Stories | C2: Points | D2: % of total
A3: MVP | B3: =COUNTIF('User Stories'!$I$2:$I$200,$A3) | C3: =SUMIF('User Stories'!$I$2:$I$200,$A3,'User Stories'!$H$2:$H$200) | D3: =IF($C$6=0,0,C3/$C$6)
A4: R1.1 | B4: =COUNTIF('User Stories'!$I$2:$I$200,$A4) | C4: =SUMIF('User Stories'!$I$2:$I$200,$A4,'User Stories'!$H$2:$H$200) | D4: =IF($C$6=0,0,C4/$C$6)
A5: R2 | B5: =COUNTIF('User Stories'!$I$2:$I$200,$A5) | C5: =SUMIF('User Stories'!$I$2:$I$200,$A5,'User Stories'!$H$2:$H$200) | D5: =IF($C$6=0,0,C5/$C$6)
A6: TOTAL | B6: =SUM(B3:B5) | C6: =SUM(C3:C5)
A8: POINTS BY PRIORITY
A9: Priority | B9: Stories | C9: Points
A10: Must | B10: =COUNTIF('User Stories'!$G$2:$G$200,$A10) | C10: =SUMIF('User Stories'!$G$2:$G$200,$A10,'User Stories'!$H$2:$H$200)
A11: Should | B11: =COUNTIF('User Stories'!$G$2:$G$200,$A11) | C11: =SUMIF('User Stories'!$G$2:$G$200,$A11,'User Stories'!$H$2:$H$200)
A12: Could | B12: =COUNTIF('User Stories'!$G$2:$G$200,$A12) | C12: =SUMIF('User Stories'!$G$2:$G$200,$A12,'User Stories'!$H$2:$H$200)
A13: TOTAL | B13: =SUM(B10:B12) | C13: =SUM(C10:C12)
A15: MVP POINTS BY EPIC
A16: Epic ID | B16: Epic Name | C16: MVP Points | D16: All Points
A17: E01 | B17: Foundation & Platform Setup | C17: =SUMIFS('User Stories'!$H$2:$H$200,'User Stories'!$B$2:$B$200,$A17,'User Stories'!$I$2:$I$200,"MVP") | D17: =SUMIF('User Stories'!$B$2:$B$200,$A17,'User Stories'!$H$2:$H$200)
A18: E02 | B18: Onboarding, Auth & Account | C18: =SUMIFS('User Stories'!$H$2:$H$200,'User Stories'!$B$2:$B$200,$A18,'User Stories'!$I$2:$I$200,"MVP") | D18: =SUMIF('User Stories'!$B$2:$B$200,$A18,'User Stories'!$H$2:$H$200)
A19: E03 | B19: Birth Data Capture & Time/Geo Resolution | C19: =SUMIFS('User Stories'!$H$2:$H$200,'User Stories'!$B$2:$B$200,$A19,'User Stories'!$I$2:$I$200,"MVP") | D19: =SUMIF('User Stories'!$B$2:$B$200,$A19,'User Stories'!$H$2:$H$200)
A20: E04 | B20: Vedic Calculation Engine (AGPL, client-side) | C20: =SUMIFS('User Stories'!$H$2:$H$200,'User Stories'!$B$2:$B$200,$A20,'User Stories'!$I$2:$I$200,"MVP") | D20: =SUMIF('User Stories'!$B$2:$B$200,$A20,'User Stories'!$H$2:$H$200)
A21: E05 | B21: Kundali Rendering & Free Insights | C21: =SUMIFS('User Stories'!$H$2:$H$200,'User Stories'!$B$2:$B$200,$A21,'User Stories'!$I$2:$I$200,"MVP") | D21: =SUMIF('User Stories'!$B$2:$B$200,$A21,'User Stories'!$H$2:$H$200)
A22: E16 | B22: Career & Industry Fit (free feature) | C22: =SUMIFS('User Stories'!$H$2:$H$200,'User Stories'!$B$2:$B$200,$A22,'User Stories'!$I$2:$I$200,"MVP") | D22: =SUMIF('User Stories'!$B$2:$B$200,$A22,'User Stories'!$H$2:$H$200)
A23: E06 | B23: Expert Kundali Evaluation - Customer Flow | C23: =SUMIFS('User Stories'!$H$2:$H$200,'User Stories'!$B$2:$B$200,$A23,'User Stories'!$I$2:$I$200,"MVP") | D23: =SUMIF('User Stories'!$B$2:$B$200,$A23,'User Stories'!$H$2:$H$200)
A24: E07 | B24: Astrologer Console (Expert Side) | C24: =SUMIFS('User Stories'!$H$2:$H$200,'User Stories'!$B$2:$B$200,$A24,'User Stories'!$I$2:$I$200,"MVP") | D24: =SUMIF('User Stories'!$B$2:$B$200,$A24,'User Stories'!$H$2:$H$200)
A25: E08 | B25: Payments, Billing & German Tax | C25: =SUMIFS('User Stories'!$H$2:$H$200,'User Stories'!$B$2:$B$200,$A25,'User Stories'!$I$2:$I$200,"MVP") | D25: =SUMIF('User Stories'!$B$2:$B$200,$A25,'User Stories'!$H$2:$H$200)
A26: E09 | B26: Localization & German Content | C26: =SUMIFS('User Stories'!$H$2:$H$200,'User Stories'!$B$2:$B$200,$A26,'User Stories'!$I$2:$I$200,"MVP") | D26: =SUMIF('User Stories'!$B$2:$B$200,$A26,'User Stories'!$H$2:$H$200)
A27: E10 | B27: Notifications & Engagement | C27: =SUMIFS('User Stories'!$H$2:$H$200,'User Stories'!$B$2:$B$200,$A27,'User Stories'!$I$2:$I$200,"MVP") | D27: =SUMIF('User Stories'!$B$2:$B$200,$A27,'User Stories'!$H$2:$H$200)
A28: E11 | B28: GDPR, Privacy & Legal Compliance | C28: =SUMIFS('User Stories'!$H$2:$H$200,'User Stories'!$B$2:$B$200,$A28,'User Stories'!$I$2:$I$200,"MVP") | D28: =SUMIF('User Stories'!$B$2:$B$200,$A28,'User Stories'!$H$2:$H$200)
... A32: E15 | B32: Post-MVP: Matchmaking, Horoscopes & Consultations | C32: =SUMIFS('User Stories'!$H$2:$H$200,'User Stories'!$B$2:$B$200,$A32,'User Stories'!$I$2:$I$200,"MVP") | D32: =SUMIF('User Stories'!$B$2:$B$200,$A32,'User Stories'!$H$2:$H$200)
B33: TOTAL | C33: =SUM(C17:C32) | D33: =SUM(D17:D32)
